2024-06-21 12:32:02,356 INFO    StreamThr :201236 [internal.py:wandb_internal():88] W&B internal server running at pid: 201236, started at: 2024-06-21 12:32:02.355693
2024-06-21 12:32:02,356 DEBUG   HandlerThread:201236 [handler.py:handle_request():158] handle_request: status
2024-06-21 12:32:02,361 INFO    WriterThread:201236 [datastore.py:open_for_write():87] open: C:\Users\Tian\Desktop\gxr\cognitive-belief-driven-qlearning\cognitive-belief-driven-qlearning\wandb\run-20240621_123202-44el879g\run-44el879g.wandb
2024-06-21 12:32:02,361 DEBUG   SenderThread:201236 [sender.py:send():379] send: header
2024-06-21 12:32:02,361 DEBUG   SenderThread:201236 [sender.py:send():379] send: run
2024-06-21 12:32:02,969 ERROR   SenderThread:201236 [internal_api.py:execute():344] 403 response executing GraphQL.
2024-06-21 12:32:02,969 ERROR   SenderThread:201236 [internal_api.py:execute():345] {"errors":[{"message":"permission denied","path":["upsertBucket"],"extensions":{"code":"PERMISSION_ERROR"}}],"data":{"upsertBucket":null}}
2024-06-21 12:32:02,972 ERROR   SenderThread:201236 [sender.py:send_run():1009] It appears that you do not have permission to access the requested resource. Please reach out to the project owner to grant you access. If you have the correct permissions, verify that there are no issues with your networking setup.(Error 403: Forbidden)
Traceback (most recent call last):
  File "C:\Users\Tian\anaconda3\envs\cbdq\lib\site-packages\wandb\sdk\lib\retry.py", line 131, in __call__
    result = self._call_fn(*args, **kwargs)
  File "C:\Users\Tian\anaconda3\envs\cbdq\lib\site-packages\wandb\sdk\internal\internal_api.py", line 340, in execute
    return self.client.execute(*args, **kwargs)  # type: ignore
  File "C:\Users\Tian\anaconda3\envs\cbdq\lib\site-packages\wandb\vendor\gql-0.2.0\wandb_gql\client.py", line 52, in execute
    result = self._get_result(document, *args, **kwargs)
  File "C:\Users\Tian\anaconda3\envs\cbdq\lib\site-packages\wandb\vendor\gql-0.2.0\wandb_gql\client.py", line 60, in _get_result
    return self.transport.execute(document, *args, **kwargs)
  File "C:\Users\Tian\anaconda3\envs\cbdq\lib\site-packages\wandb\sdk\lib\gql_request.py", line 59, in execute
    request.raise_for_status()
  File "C:\Users\Tian\anaconda3\envs\cbdq\lib\site-packages\requests\models.py", line 1021, in raise_for_status
    raise HTTPError(http_error_msg, response=self)
requests.exceptions.HTTPError: 403 Client Error: Forbidden for url: https://api.wandb.ai/graphql

During handling of the above exception, another exception occurred:

Traceback (most recent call last):
  File "C:\Users\Tian\anaconda3\envs\cbdq\lib\site-packages\wandb\sdk\internal\sender.py", line 1007, in send_run
    server_run = self._init_run(run, config_value_dict)
  File "C:\Users\Tian\anaconda3\envs\cbdq\lib\site-packages\wandb\sdk\internal\sender.py", line 1093, in _init_run
    commit=run.git.commit or None,
  File "C:\Users\Tian\anaconda3\envs\cbdq\lib\site-packages\wandb\apis\normalize.py", line 73, in wrapper
    raise err
  File "C:\Users\Tian\anaconda3\envs\cbdq\lib\site-packages\wandb\apis\normalize.py", line 41, in wrapper
    return func(*args, **kwargs)
  File "C:\Users\Tian\anaconda3\envs\cbdq\lib\site-packages\wandb\sdk\internal\internal_api.py", line 2192, in upsert_run
    **kwargs,
  File "C:\Users\Tian\anaconda3\envs\cbdq\lib\site-packages\wandb\sdk\internal\internal_api.py", line 315, in gql
    **kwargs,
  File "C:\Users\Tian\anaconda3\envs\cbdq\lib\site-packages\wandb\sdk\lib\retry.py", line 147, in __call__
    retry_timedelta_triggered = check_retry_fn(e)
  File "C:\Users\Tian\anaconda3\envs\cbdq\lib\site-packages\wandb\util.py", line 965, in check_retry_fn
    return fallback_retry_fn(e)
  File "C:\Users\Tian\anaconda3\envs\cbdq\lib\site-packages\wandb\util.py", line 908, in no_retry_auth
    "It appears that you do not have permission to access the requested resource. "
wandb.errors.CommError: It appears that you do not have permission to access the requested resource. Please reach out to the project owner to grant you access. If you have the correct permissions, verify that there are no issues with your networking setup.(Error 403: Forbidden)
2024-06-21 12:32:03,541 DEBUG   HandlerThread:201236 [handler.py:handle_request():158] handle_request: shutdown
2024-06-21 12:32:03,541 INFO    HandlerThread:201236 [handler.py:finish():882] shutting down handler
2024-06-21 12:32:03,985 INFO    SenderThread:201236 [sender.py:finish():1608] shutting down sender
2024-06-21 12:32:04,373 INFO    WriterThread:201236 [datastore.py:close():296] close: C:\Users\Tian\Desktop\gxr\cognitive-belief-driven-qlearning\cognitive-belief-driven-qlearning\wandb\run-20240621_123202-44el879g\run-44el879g.wandb
